# Generated by Django 4.2.25 on 2025-10-28 09:42

from django.db import migrations, models


class Migration(migrations.Migration):

    dependencies = [
        ('ai_tracking', '0003_aipromptconfig'),
    ]

    operations = [
        migrations.AddField(
            model_name='aipromptconfig',
            name='consecutive_failures',
            field=models.IntegerField(default=0, help_text='Consecutive failures without success'),
        ),
        migrations.AddField(
            model_name='aipromptconfig',
            name='last_error_code',
            field=models.CharField(blank=True, max_length=200),
        ),
        migrations.AddField(
            model_name='aipromptconfig',
            name='last_error_message',
            field=models.TextField(blank=True),
        ),
        migrations.AddField(
            model_name='aipromptconfig',
            name='last_error_traceback',
            field=models.TextField(blank=True),
        ),
        migrations.AddField(
            model_name='aipromptconfig',
            name='last_failed_at',
            field=models.DateTimeField(blank=True, null=True),
        ),
        migrations.AddField(
            model_name='aipromptconfig',
            name='total_failed_calls',
            field=models.IntegerField(default=0, help_text='Number of failed calls'),
        ),
        migrations.AddField(
            model_name='aiusagelog',
            name='error_code',
            field=models.CharField(blank=True, help_text='Exception class name (e.g., OpenAIError)', max_length=200),
        ),
        migrations.AddField(
            model_name='aiusagelog',
            name='error_traceback',
            field=models.TextField(blank=True, help_text='Full traceback for debugging'),
        ),
    ]
